2020-06-14 17:10:39,971 ERROR HTTPConnectionPool(host='oj-backend', port=8000): Max retries exceeded with url: /api/judge_server_heartbeat/ (Caused by NewConnectionError('<urllib3.connection.HTTPConnection object at 0x7f387e2cf048>: Failed to establish a new connection: [Errno 111] Connection refused',))
Traceback (most recent call last):
  File "/usr/local/lib/python3.5/dist-packages/urllib3/connection.py", line 159, in _new_conn
    (self._dns_host, self.port), self.timeout, **extra_kw)
  File "/usr/local/lib/python3.5/dist-packages/urllib3/util/connection.py", line 80, in create_connection
    raise err
  File "/usr/local/lib/python3.5/dist-packages/urllib3/util/connection.py", line 70, in create_connection
    sock.connect(sa)
ConnectionRefusedError: [Errno 111] Connection refused

During handling of the above exception, another exception occurred:

Traceback (most recent call last):
  File "/usr/local/lib/python3.5/dist-packages/urllib3/connectionpool.py", line 600, in urlopen
    chunked=chunked)
  File "/usr/local/lib/python3.5/dist-packages/urllib3/connectionpool.py", line 354, in _make_request
    conn.request(method, url, **httplib_request_kw)
  File "/usr/lib/python3.5/http/client.py", line 1106, in request
    self._send_request(method, url, body, headers)
  File "/usr/lib/python3.5/http/client.py", line 1151, in _send_request
    self.endheaders(body)
  File "/usr/lib/python3.5/http/client.py", line 1102, in endheaders
    self._send_output(message_body)
  File "/usr/lib/python3.5/http/client.py", line 934, in _send_output
    self.send(msg)
  File "/usr/lib/python3.5/http/client.py", line 877, in send
    self.connect()
  File "/usr/local/lib/python3.5/dist-packages/urllib3/connection.py", line 181, in connect
    conn = self._new_conn()
  File "/usr/local/lib/python3.5/dist-packages/urllib3/connection.py", line 168, in _new_conn
    self, "Failed to establish a new connection: %s" % e)
urllib3.exceptions.NewConnectionError: <urllib3.connection.HTTPConnection object at 0x7f387e2cf048>: Failed to establish a new connection: [Errno 111] Connection refused

During handling of the above exception, another exception occurred:

Traceback (most recent call last):
  File "/usr/local/lib/python3.5/dist-packages/requests/adapters.py", line 449, in send
    timeout=timeout
  File "/usr/local/lib/python3.5/dist-packages/urllib3/connectionpool.py", line 638, in urlopen
    _stacktrace=sys.exc_info()[2])
  File "/usr/local/lib/python3.5/dist-packages/urllib3/util/retry.py", line 398, in increment
    raise MaxRetryError(_pool, url, error or ResponseError(cause))
urllib3.exceptions.MaxRetryError: HTTPConnectionPool(host='oj-backend', port=8000): Max retries exceeded with url: /api/judge_server_heartbeat/ (Caused by NewConnectionError('<urllib3.connection.HTTPConnection object at 0x7f387e2cf048>: Failed to establish a new connection: [Errno 111] Connection refused',))

During handling of the above exception, another exception occurred:

Traceback (most recent call last):
  File "/code/service.py", line 19, in _request
    "Content-Type": "application/json"}, timeout=5).text
  File "/usr/local/lib/python3.5/dist-packages/requests/api.py", line 116, in post
    return request('post', url, data=data, json=json, **kwargs)
  File "/usr/local/lib/python3.5/dist-packages/requests/api.py", line 60, in request
    return session.request(method=method, url=url, **kwargs)
  File "/usr/local/lib/python3.5/dist-packages/requests/sessions.py", line 533, in request
    resp = self.send(prep, **send_kwargs)
  File "/usr/local/lib/python3.5/dist-packages/requests/sessions.py", line 646, in send
    r = adapter.send(request, **kwargs)
  File "/usr/local/lib/python3.5/dist-packages/requests/adapters.py", line 516, in send
    raise ConnectionError(e, request=request)
requests.exceptions.ConnectionError: HTTPConnectionPool(host='oj-backend', port=8000): Max retries exceeded with url: /api/judge_server_heartbeat/ (Caused by NewConnectionError('<urllib3.connection.HTTPConnection object at 0x7f387e2cf048>: Failed to establish a new connection: [Errno 111] Connection refused',))
2020-06-14 17:10:39,973 ERROR 
Traceback (most recent call last):
  File "/usr/local/lib/python3.5/dist-packages/urllib3/connection.py", line 159, in _new_conn
    (self._dns_host, self.port), self.timeout, **extra_kw)
  File "/usr/local/lib/python3.5/dist-packages/urllib3/util/connection.py", line 80, in create_connection
    raise err
  File "/usr/local/lib/python3.5/dist-packages/urllib3/util/connection.py", line 70, in create_connection
    sock.connect(sa)
ConnectionRefusedError: [Errno 111] Connection refused

During handling of the above exception, another exception occurred:

Traceback (most recent call last):
  File "/usr/local/lib/python3.5/dist-packages/urllib3/connectionpool.py", line 600, in urlopen
    chunked=chunked)
  File "/usr/local/lib/python3.5/dist-packages/urllib3/connectionpool.py", line 354, in _make_request
    conn.request(method, url, **httplib_request_kw)
  File "/usr/lib/python3.5/http/client.py", line 1106, in request
    self._send_request(method, url, body, headers)
  File "/usr/lib/python3.5/http/client.py", line 1151, in _send_request
    self.endheaders(body)
  File "/usr/lib/python3.5/http/client.py", line 1102, in endheaders
    self._send_output(message_body)
  File "/usr/lib/python3.5/http/client.py", line 934, in _send_output
    self.send(msg)
  File "/usr/lib/python3.5/http/client.py", line 877, in send
    self.connect()
  File "/usr/local/lib/python3.5/dist-packages/urllib3/connection.py", line 181, in connect
    conn = self._new_conn()
  File "/usr/local/lib/python3.5/dist-packages/urllib3/connection.py", line 168, in _new_conn
    self, "Failed to establish a new connection: %s" % e)
urllib3.exceptions.NewConnectionError: <urllib3.connection.HTTPConnection object at 0x7f387e2cf048>: Failed to establish a new connection: [Errno 111] Connection refused

During handling of the above exception, another exception occurred:

Traceback (most recent call last):
  File "/usr/local/lib/python3.5/dist-packages/requests/adapters.py", line 449, in send
    timeout=timeout
  File "/usr/local/lib/python3.5/dist-packages/urllib3/connectionpool.py", line 638, in urlopen
    _stacktrace=sys.exc_info()[2])
  File "/usr/local/lib/python3.5/dist-packages/urllib3/util/retry.py", line 398, in increment
    raise MaxRetryError(_pool, url, error or ResponseError(cause))
urllib3.exceptions.MaxRetryError: HTTPConnectionPool(host='oj-backend', port=8000): Max retries exceeded with url: /api/judge_server_heartbeat/ (Caused by NewConnectionError('<urllib3.connection.HTTPConnection object at 0x7f387e2cf048>: Failed to establish a new connection: [Errno 111] Connection refused',))

During handling of the above exception, another exception occurred:

Traceback (most recent call last):
  File "/code/service.py", line 19, in _request
    "Content-Type": "application/json"}, timeout=5).text
  File "/usr/local/lib/python3.5/dist-packages/requests/api.py", line 116, in post
    return request('post', url, data=data, json=json, **kwargs)
  File "/usr/local/lib/python3.5/dist-packages/requests/api.py", line 60, in request
    return session.request(method=method, url=url, **kwargs)
  File "/usr/local/lib/python3.5/dist-packages/requests/sessions.py", line 533, in request
    resp = self.send(prep, **send_kwargs)
  File "/usr/local/lib/python3.5/dist-packages/requests/sessions.py", line 646, in send
    r = adapter.send(request, **kwargs)
  File "/usr/local/lib/python3.5/dist-packages/requests/adapters.py", line 516, in send
    raise ConnectionError(e, request=request)
requests.exceptions.ConnectionError: HTTPConnectionPool(host='oj-backend', port=8000): Max retries exceeded with url: /api/judge_server_heartbeat/ (Caused by NewConnectionError('<urllib3.connection.HTTPConnection object at 0x7f387e2cf048>: Failed to establish a new connection: [Errno 111] Connection refused',))

During handling of the above exception, another exception occurred:

Traceback (most recent call last):
  File "/code/service.py", line 42, in <module>
    service.heartbeat()
  File "/code/service.py", line 35, in heartbeat
    self._request(data)
  File "/code/service.py", line 22, in _request
    raise JudgeServiceError("Heartbeat request failed")
exception.JudgeServiceError
2020-06-15 02:01:43,381 ERROR 
Traceback (most recent call last):
  File "/code/server.py", line 192, in server
    ret = {"err": None, "data": getattr(JudgeServer, path)(**data)}
  File "/code/server.py", line 99, in judge
    output_dir=submission_dir)
  File "/code/compiler.py", line 42, in compile
    raise CompileError(error)
exception.CompileError
2020-06-15 02:18:12,473 ERROR 
Traceback (most recent call last):
  File "/code/server.py", line 192, in server
    ret = {"err": None, "data": getattr(JudgeServer, path)(**data)}
  File "/code/server.py", line 99, in judge
    output_dir=submission_dir)
  File "/code/compiler.py", line 42, in compile
    raise CompileError(error)
exception.CompileError
2020-06-15 03:26:29,949 ERROR 
Traceback (most recent call last):
  File "/code/server.py", line 192, in server
    ret = {"err": None, "data": getattr(JudgeServer, path)(**data)}
  File "/code/server.py", line 99, in judge
    output_dir=submission_dir)
  File "/code/compiler.py", line 42, in compile
    raise CompileError(error)
exception.CompileError
2020-06-15 15:05:29,755 ERROR 
Traceback (most recent call last):
  File "/code/server.py", line 192, in server
    ret = {"err": None, "data": getattr(JudgeServer, path)(**data)}
  File "/code/server.py", line 99, in judge
    output_dir=submission_dir)
  File "/code/compiler.py", line 42, in compile
    raise CompileError(error)
exception.CompileError
2020-06-15 15:06:17,217 ERROR 
Traceback (most recent call last):
  File "/code/server.py", line 192, in server
    ret = {"err": None, "data": getattr(JudgeServer, path)(**data)}
  File "/code/server.py", line 99, in judge
    output_dir=submission_dir)
  File "/code/compiler.py", line 42, in compile
    raise CompileError(error)
exception.CompileError
2020-06-15 15:09:21,582 ERROR 
Traceback (most recent call last):
  File "/code/server.py", line 192, in server
    ret = {"err": None, "data": getattr(JudgeServer, path)(**data)}
  File "/code/server.py", line 99, in judge
    output_dir=submission_dir)
  File "/code/compiler.py", line 42, in compile
    raise CompileError(error)
exception.CompileError
2020-06-16 02:59:32,695 ERROR 
Traceback (most recent call last):
  File "/code/server.py", line 192, in server
    ret = {"err": None, "data": getattr(JudgeServer, path)(**data)}
  File "/code/server.py", line 99, in judge
    output_dir=submission_dir)
  File "/code/compiler.py", line 42, in compile
    raise CompileError(error)
exception.CompileError
2020-06-16 11:43:37,498 ERROR 
Traceback (most recent call last):
  File "/code/server.py", line 192, in server
    ret = {"err": None, "data": getattr(JudgeServer, path)(**data)}
  File "/code/server.py", line 99, in judge
    output_dir=submission_dir)
  File "/code/compiler.py", line 42, in compile
    raise CompileError(error)
exception.CompileError
2020-06-16 11:44:26,999 ERROR 
Traceback (most recent call last):
  File "/code/server.py", line 192, in server
    ret = {"err": None, "data": getattr(JudgeServer, path)(**data)}
  File "/code/server.py", line 99, in judge
    output_dir=submission_dir)
  File "/code/compiler.py", line 42, in compile
    raise CompileError(error)
exception.CompileError
2020-06-16 11:47:26,263 ERROR 
Traceback (most recent call last):
  File "/code/server.py", line 192, in server
    ret = {"err": None, "data": getattr(JudgeServer, path)(**data)}
  File "/code/server.py", line 99, in judge
    output_dir=submission_dir)
  File "/code/compiler.py", line 42, in compile
    raise CompileError(error)
exception.CompileError
2020-06-16 11:47:38,480 ERROR 
Traceback (most recent call last):
  File "/code/server.py", line 192, in server
    ret = {"err": None, "data": getattr(JudgeServer, path)(**data)}
  File "/code/server.py", line 99, in judge
    output_dir=submission_dir)
  File "/code/compiler.py", line 42, in compile
    raise CompileError(error)
exception.CompileError
2020-06-16 11:47:57,102 ERROR 
Traceback (most recent call last):
  File "/code/server.py", line 192, in server
    ret = {"err": None, "data": getattr(JudgeServer, path)(**data)}
  File "/code/server.py", line 99, in judge
    output_dir=submission_dir)
  File "/code/compiler.py", line 42, in compile
    raise CompileError(error)
exception.CompileError
2020-06-16 11:51:22,743 ERROR 
Traceback (most recent call last):
  File "/code/server.py", line 171, in compile_spj
    output_dir=SPJ_EXE_DIR)
  File "/code/compiler.py", line 42, in compile
    raise CompileError(error)
exception.CompileError

During handling of the above exception, another exception occurred:

Traceback (most recent call last):
  File "/code/server.py", line 192, in server
    ret = {"err": None, "data": getattr(JudgeServer, path)(**data)}
  File "/code/server.py", line 176, in compile_spj
    raise SPJCompileError(e.message)
exception.SPJCompileError
2020-06-16 12:09:52,282 ERROR 
Traceback (most recent call last):
  File "/code/server.py", line 171, in compile_spj
    output_dir=SPJ_EXE_DIR)
  File "/code/compiler.py", line 42, in compile
    raise CompileError(error)
exception.CompileError

During handling of the above exception, another exception occurred:

Traceback (most recent call last):
  File "/code/server.py", line 192, in server
    ret = {"err": None, "data": getattr(JudgeServer, path)(**data)}
  File "/code/server.py", line 176, in compile_spj
    raise SPJCompileError(e.message)
exception.SPJCompileError
2020-06-16 12:09:55,706 ERROR 
Traceback (most recent call last):
  File "/code/server.py", line 171, in compile_spj
    output_dir=SPJ_EXE_DIR)
  File "/code/compiler.py", line 42, in compile
    raise CompileError(error)
exception.CompileError

During handling of the above exception, another exception occurred:

Traceback (most recent call last):
  File "/code/server.py", line 192, in server
    ret = {"err": None, "data": getattr(JudgeServer, path)(**data)}
  File "/code/server.py", line 176, in compile_spj
    raise SPJCompileError(e.message)
exception.SPJCompileError
2020-06-16 12:11:28,506 ERROR 
Traceback (most recent call last):
  File "/code/server.py", line 171, in compile_spj
    output_dir=SPJ_EXE_DIR)
  File "/code/compiler.py", line 42, in compile
    raise CompileError(error)
exception.CompileError

During handling of the above exception, another exception occurred:

Traceback (most recent call last):
  File "/code/server.py", line 192, in server
    ret = {"err": None, "data": getattr(JudgeServer, path)(**data)}
  File "/code/server.py", line 176, in compile_spj
    raise SPJCompileError(e.message)
exception.SPJCompileError
2020-06-16 12:11:37,256 ERROR 
Traceback (most recent call last):
  File "/code/server.py", line 171, in compile_spj
    output_dir=SPJ_EXE_DIR)
  File "/code/compiler.py", line 42, in compile
    raise CompileError(error)
exception.CompileError

During handling of the above exception, another exception occurred:

Traceback (most recent call last):
  File "/code/server.py", line 192, in server
    ret = {"err": None, "data": getattr(JudgeServer, path)(**data)}
  File "/code/server.py", line 176, in compile_spj
    raise SPJCompileError(e.message)
exception.SPJCompileError
2020-06-16 12:24:33,440 WARNING %s does not exists, spj src will be recompiled
2020-06-16 12:24:33,719 ERROR 
Traceback (most recent call last):
  File "/code/server.py", line 192, in server
    ret = {"err": None, "data": getattr(JudgeServer, path)(**data)}
  File "/code/server.py", line 99, in judge
    output_dir=submission_dir)
  File "/code/compiler.py", line 42, in compile
    raise CompileError(error)
exception.CompileError
2020-06-16 12:26:36,902 ERROR 
Traceback (most recent call last):
  File "/code/server.py", line 171, in compile_spj
    output_dir=SPJ_EXE_DIR)
  File "/code/compiler.py", line 42, in compile
    raise CompileError(error)
exception.CompileError

During handling of the above exception, another exception occurred:

Traceback (most recent call last):
  File "/code/server.py", line 192, in server
    ret = {"err": None, "data": getattr(JudgeServer, path)(**data)}
  File "/code/server.py", line 176, in compile_spj
    raise SPJCompileError(e.message)
exception.SPJCompileError
2020-06-16 12:27:07,256 ERROR 
Traceback (most recent call last):
  File "/code/server.py", line 192, in server
    ret = {"err": None, "data": getattr(JudgeServer, path)(**data)}
  File "/code/server.py", line 99, in judge
    output_dir=submission_dir)
  File "/code/compiler.py", line 42, in compile
    raise CompileError(error)
exception.CompileError
2020-06-16 12:31:53,759 WARNING %s does not exists, spj src will be recompiled
2020-06-16 12:31:54,044 ERROR 
Traceback (most recent call last):
  File "/code/server.py", line 192, in server
    ret = {"err": None, "data": getattr(JudgeServer, path)(**data)}
  File "/code/server.py", line 99, in judge
    output_dir=submission_dir)
  File "/code/compiler.py", line 42, in compile
    raise CompileError(error)
exception.CompileError
2020-06-16 12:32:38,577 ERROR 
Traceback (most recent call last):
  File "/code/server.py", line 192, in server
    ret = {"err": None, "data": getattr(JudgeServer, path)(**data)}
  File "/code/server.py", line 99, in judge
    output_dir=submission_dir)
  File "/code/compiler.py", line 42, in compile
    raise CompileError(error)
exception.CompileError
2020-06-16 12:33:06,085 ERROR 
Traceback (most recent call last):
  File "/code/server.py", line 192, in server
    ret = {"err": None, "data": getattr(JudgeServer, path)(**data)}
  File "/code/server.py", line 99, in judge
    output_dir=submission_dir)
  File "/code/compiler.py", line 42, in compile
    raise CompileError(error)
exception.CompileError
2020-06-16 12:33:18,689 ERROR 
Traceback (most recent call last):
  File "/code/server.py", line 192, in server
    ret = {"err": None, "data": getattr(JudgeServer, path)(**data)}
  File "/code/server.py", line 99, in judge
    output_dir=submission_dir)
  File "/code/compiler.py", line 42, in compile
    raise CompileError(error)
exception.CompileError
2020-06-16 12:35:13,970 ERROR 
Traceback (most recent call last):
  File "/code/server.py", line 171, in compile_spj
    output_dir=SPJ_EXE_DIR)
  File "/code/compiler.py", line 42, in compile
    raise CompileError(error)
exception.CompileError

During handling of the above exception, another exception occurred:

Traceback (most recent call last):
  File "/code/server.py", line 192, in server
    ret = {"err": None, "data": getattr(JudgeServer, path)(**data)}
  File "/code/server.py", line 176, in compile_spj
    raise SPJCompileError(e.message)
exception.SPJCompileError
2020-06-16 12:36:30,479 ERROR 
Traceback (most recent call last):
  File "/code/server.py", line 192, in server
    ret = {"err": None, "data": getattr(JudgeServer, path)(**data)}
  File "/code/server.py", line 99, in judge
    output_dir=submission_dir)
  File "/code/compiler.py", line 42, in compile
    raise CompileError(error)
exception.CompileError
2020-06-16 12:40:41,072 ERROR 
Traceback (most recent call last):
  File "/code/server.py", line 192, in server
    ret = {"err": None, "data": getattr(JudgeServer, path)(**data)}
  File "/code/server.py", line 99, in judge
    output_dir=submission_dir)
  File "/code/compiler.py", line 42, in compile
    raise CompileError(error)
exception.CompileError
2020-06-16 12:40:53,224 ERROR 
Traceback (most recent call last):
  File "/code/server.py", line 192, in server
    ret = {"err": None, "data": getattr(JudgeServer, path)(**data)}
  File "/code/server.py", line 99, in judge
    output_dir=submission_dir)
  File "/code/compiler.py", line 42, in compile
    raise CompileError(error)
exception.CompileError
2020-06-16 12:41:07,646 ERROR 
Traceback (most recent call last):
  File "/code/server.py", line 192, in server
    ret = {"err": None, "data": getattr(JudgeServer, path)(**data)}
  File "/code/server.py", line 99, in judge
    output_dir=submission_dir)
  File "/code/compiler.py", line 42, in compile
    raise CompileError(error)
exception.CompileError
2020-06-16 12:41:14,861 ERROR 
Traceback (most recent call last):
  File "/code/server.py", line 192, in server
    ret = {"err": None, "data": getattr(JudgeServer, path)(**data)}
  File "/code/server.py", line 99, in judge
    output_dir=submission_dir)
  File "/code/compiler.py", line 42, in compile
    raise CompileError(error)
exception.CompileError
2020-06-16 12:43:28,562 ERROR 
Traceback (most recent call last):
  File "/code/server.py", line 171, in compile_spj
    output_dir=SPJ_EXE_DIR)
  File "/code/compiler.py", line 42, in compile
    raise CompileError(error)
exception.CompileError

During handling of the above exception, another exception occurred:

Traceback (most recent call last):
  File "/code/server.py", line 192, in server
    ret = {"err": None, "data": getattr(JudgeServer, path)(**data)}
  File "/code/server.py", line 176, in compile_spj
    raise SPJCompileError(e.message)
exception.SPJCompileError
2020-06-16 12:44:25,373 WARNING %s does not exists, spj src will be recompiled
2020-06-16 12:47:20,358 ERROR 
Traceback (most recent call last):
  File "/code/server.py", line 192, in server
    ret = {"err": None, "data": getattr(JudgeServer, path)(**data)}
  File "/code/server.py", line 99, in judge
    output_dir=submission_dir)
  File "/code/compiler.py", line 42, in compile
    raise CompileError(error)
exception.CompileError
2020-06-16 12:48:33,038 ERROR 
Traceback (most recent call last):
  File "/code/server.py", line 192, in server
    ret = {"err": None, "data": getattr(JudgeServer, path)(**data)}
  File "/code/server.py", line 99, in judge
    output_dir=submission_dir)
  File "/code/compiler.py", line 42, in compile
    raise CompileError(error)
exception.CompileError
2020-06-16 12:49:37,499 ERROR 
Traceback (most recent call last):
  File "/code/server.py", line 192, in server
    ret = {"err": None, "data": getattr(JudgeServer, path)(**data)}
  File "/code/server.py", line 99, in judge
    output_dir=submission_dir)
  File "/code/compiler.py", line 42, in compile
    raise CompileError(error)
exception.CompileError
2020-06-16 12:49:52,470 ERROR 
Traceback (most recent call last):
  File "/code/server.py", line 192, in server
    ret = {"err": None, "data": getattr(JudgeServer, path)(**data)}
  File "/code/server.py", line 99, in judge
    output_dir=submission_dir)
  File "/code/compiler.py", line 42, in compile
    raise CompileError(error)
exception.CompileError
2020-06-16 12:50:46,132 ERROR 
Traceback (most recent call last):
  File "/code/server.py", line 192, in server
    ret = {"err": None, "data": getattr(JudgeServer, path)(**data)}
  File "/code/server.py", line 99, in judge
    output_dir=submission_dir)
  File "/code/compiler.py", line 42, in compile
    raise CompileError(error)
exception.CompileError
2020-06-16 12:51:59,421 ERROR 
Traceback (most recent call last):
  File "/code/server.py", line 192, in server
    ret = {"err": None, "data": getattr(JudgeServer, path)(**data)}
  File "/code/server.py", line 99, in judge
    output_dir=submission_dir)
  File "/code/compiler.py", line 42, in compile
    raise CompileError(error)
exception.CompileError
2020-06-16 12:54:35,013 ERROR 
Traceback (most recent call last):
  File "/code/server.py", line 192, in server
    ret = {"err": None, "data": getattr(JudgeServer, path)(**data)}
  File "/code/server.py", line 99, in judge
    output_dir=submission_dir)
  File "/code/compiler.py", line 42, in compile
    raise CompileError(error)
exception.CompileError
2020-06-16 12:55:23,376 ERROR 
Traceback (most recent call last):
  File "/code/server.py", line 192, in server
    ret = {"err": None, "data": getattr(JudgeServer, path)(**data)}
  File "/code/server.py", line 99, in judge
    output_dir=submission_dir)
  File "/code/compiler.py", line 42, in compile
    raise CompileError(error)
exception.CompileError
2020-06-16 12:55:42,853 ERROR 
Traceback (most recent call last):
  File "/code/server.py", line 192, in server
    ret = {"err": None, "data": getattr(JudgeServer, path)(**data)}
  File "/code/server.py", line 99, in judge
    output_dir=submission_dir)
  File "/code/compiler.py", line 42, in compile
    raise CompileError(error)
exception.CompileError
2020-06-16 12:57:25,967 ERROR 
Traceback (most recent call last):
  File "/code/server.py", line 192, in server
    ret = {"err": None, "data": getattr(JudgeServer, path)(**data)}
  File "/code/server.py", line 99, in judge
    output_dir=submission_dir)
  File "/code/compiler.py", line 42, in compile
    raise CompileError(error)
exception.CompileError
2020-06-16 12:59:30,943 ERROR 
Traceback (most recent call last):
  File "/code/server.py", line 171, in compile_spj
    output_dir=SPJ_EXE_DIR)
  File "/code/compiler.py", line 42, in compile
    raise CompileError(error)
exception.CompileError

During handling of the above exception, another exception occurred:

Traceback (most recent call last):
  File "/code/server.py", line 192, in server
    ret = {"err": None, "data": getattr(JudgeServer, path)(**data)}
  File "/code/server.py", line 176, in compile_spj
    raise SPJCompileError(e.message)
exception.SPJCompileError
2020-06-16 12:59:48,003 ERROR 
Traceback (most recent call last):
  File "/code/server.py", line 171, in compile_spj
    output_dir=SPJ_EXE_DIR)
  File "/code/compiler.py", line 42, in compile
    raise CompileError(error)
exception.CompileError

During handling of the above exception, another exception occurred:

Traceback (most recent call last):
  File "/code/server.py", line 192, in server
    ret = {"err": None, "data": getattr(JudgeServer, path)(**data)}
  File "/code/server.py", line 176, in compile_spj
    raise SPJCompileError(e.message)
exception.SPJCompileError
2020-06-16 13:09:50,869 ERROR 
Traceback (most recent call last):
  File "/code/server.py", line 192, in server
    ret = {"err": None, "data": getattr(JudgeServer, path)(**data)}
  File "/code/server.py", line 99, in judge
    output_dir=submission_dir)
  File "/code/compiler.py", line 42, in compile
    raise CompileError(error)
exception.CompileError
2020-06-16 13:10:36,004 ERROR 
Traceback (most recent call last):
  File "/code/server.py", line 192, in server
    ret = {"err": None, "data": getattr(JudgeServer, path)(**data)}
  File "/code/server.py", line 99, in judge
    output_dir=submission_dir)
  File "/code/compiler.py", line 42, in compile
    raise CompileError(error)
exception.CompileError
2020-06-16 13:11:54,964 ERROR 
Traceback (most recent call last):
  File "/code/server.py", line 192, in server
    ret = {"err": None, "data": getattr(JudgeServer, path)(**data)}
  File "/code/server.py", line 99, in judge
    output_dir=submission_dir)
  File "/code/compiler.py", line 42, in compile
    raise CompileError(error)
exception.CompileError
2020-06-16 17:50:55,098 ERROR 
Traceback (most recent call last):
  File "/code/server.py", line 192, in server
    ret = {"err": None, "data": getattr(JudgeServer, path)(**data)}
  File "/code/server.py", line 99, in judge
    output_dir=submission_dir)
  File "/code/compiler.py", line 42, in compile
    raise CompileError(error)
exception.CompileError
2020-06-16 17:51:10,712 ERROR 
Traceback (most recent call last):
  File "/code/server.py", line 192, in server
    ret = {"err": None, "data": getattr(JudgeServer, path)(**data)}
  File "/code/server.py", line 99, in judge
    output_dir=submission_dir)
  File "/code/compiler.py", line 42, in compile
    raise CompileError(error)
exception.CompileError
2020-06-16 17:52:14,423 ERROR 
Traceback (most recent call last):
  File "/code/server.py", line 192, in server
    ret = {"err": None, "data": getattr(JudgeServer, path)(**data)}
  File "/code/server.py", line 99, in judge
    output_dir=submission_dir)
  File "/code/compiler.py", line 42, in compile
    raise CompileError(error)
exception.CompileError
2020-06-16 17:52:31,194 ERROR 
Traceback (most recent call last):
  File "/code/server.py", line 192, in server
    ret = {"err": None, "data": getattr(JudgeServer, path)(**data)}
  File "/code/server.py", line 99, in judge
    output_dir=submission_dir)
  File "/code/compiler.py", line 42, in compile
    raise CompileError(error)
exception.CompileError
2020-06-16 17:52:41,166 ERROR 
Traceback (most recent call last):
  File "/code/server.py", line 192, in server
    ret = {"err": None, "data": getattr(JudgeServer, path)(**data)}
  File "/code/server.py", line 99, in judge
    output_dir=submission_dir)
  File "/code/compiler.py", line 42, in compile
    raise CompileError(error)
exception.CompileError
